<sdf version="1.5">
  <model name="jake">
    <plugin
        filename="gz-sim-diff-drive-system"
        name="gz::sim::systems::DiffDrive">
        <left_joint>fl_wheel_joint</left_joint>
        <right_joint>fr_wheel_joint</right_joint>
        <wheel_separation>1.2</wheel_separation>
        <wheel_radius>1</wheel_radius>
        <odom_publish_frequency>1</odom_publish_frequency>
        <topic>cmd_vel</topic>
    </plugin>
    <!-- Body of the robot -->
    <link name="body">
      <visual name="body_visual"> <!-- Replace with .STL -->
        <geometry>
          <box>
            <size>1 0.5 0.3</size> <!-- Length x Width x Height -->
          </box>
        </geometry>
        <material>
          <ambient>0.8 0.2 0.2 1</ambient> <!-- Color Red -->
        </material>
      </visual>
      <collision name="body_collision">
        <geometry>
          <box>
            <size>1 0.5 0.3</size> <!-- Length x Width x Height -->
          </box>
        </geometry>
      </collision>
      <inertial>
        <mass>5.0</mass>
        <inertia>
          <ixx>0.1</ixx>
          <iyy>0.1</iyy>
          <izz>0.2</izz>
        </inertia>
      </inertial>
    </link>

    <!-- Actuated wheels -->
    <!-- Front left wheel -->
    <link name="fl_wheel">
      <visual name="fl_wheel_visual">
        <geometry>
          <cylinder>
            <radius>0.1</radius>
            <length>0.1</length>
          </cylinder>
        </geometry>
        <material>
          <ambient>0.8 0.2 0.2 1</ambient> <!-- Color Red -->
        </material>
      </visual>
      <collision name="fl_wheel_collision">
        <geometry>
          <cylinder>
            <radius>0.1</radius>
            <length>0.1</length>
          </cylinder>
        </geometry>
      </collision>
      <inertial>
        <mass>0.5</mass>
        <inertia>
          <ixx>0.002</ixx>
          <iyy>0.002</iyy>
          <izz>0.004</izz>
        </inertia>
      </inertial>
    </link>

    <joint name="fl_wheel_joint" type="revolute">
      <parent>body</parent>
      <child>fl_wheel</child>
      <axis>
        <xyz>0 1 0</xyz> <!-- Revolute axis (rotation around Y-axis) -->
      </axis>
      <limit>
        <lower>-1.0</lower>
        <upper>1.0</upper>
        <effort>10</effort>
        <velocity>1.0</velocity>
      </limit>
    </joint>

    <!-- Front right wheel -->
    <link name="fr_wheel">
      <visual name="fr_wheel_visual">
        <geometry>
          <cylinder>
            <radius>0.1</radius>
            <length>0.1</length>
          </cylinder>
        </geometry>
        <material>
          <ambient>0.8 0.2 0.2 1</ambient> <!-- Color Red -->
        </material>
      </visual>
      <collision name="fr_wheel_collision">
        <geometry>
          <cylinder>
            <radius>0.1</radius>
            <length>0.1</length>
          </cylinder>
        </geometry>
      </collision>
      <inertial>
        <mass>0.5</mass>
        <inertia>
          <ixx>0.002</ixx>
          <iyy>0.002</iyy>
          <izz>0.004</izz>
        </inertia>
      </inertial>
    </link>

    <joint name="fr_wheel_joint" type="revolute">
      <parent>body</parent>
      <child>fr_wheel</child>
      <axis>
        <xyz>0 1 0</xyz> <!-- Revolute axis (rotation around Y-axis) -->
      </axis>
      <limit>
        <lower>-1.0</lower>
        <upper>1.0</upper>
        <effort>10</effort>
        <velocity>1.0</velocity>
      </limit>
    </joint>

    <!-- Passive wheels -->
    <!-- Rear left wheel -->
    <link name="rl_wheel">
      <visual name="rl_wheel_visual">
        <geometry>
          <cylinder>
            <radius>0.1</radius>
            <length>0.1</length>
          </cylinder>
        </geometry>
        <material>
          <ambient>0.8 0.2 0.2 1</ambient> <!-- Color Red -->
        </material>
      </visual>
      <collision name="rl_wheel_collision">
        <geometry>
          <cylinder>
            <radius>0.1</radius>
            <length>0.1</length>
          </cylinder>
        </geometry>
      </collision>
      <inertial>
        <mass>0.5</mass>
        <inertia>
          <ixx>0.002</ixx>
          <iyy>0.002</iyy>
          <izz>0.004</izz>
        </inertia>
      </inertial>
    </link>

    <joint name="rl_wheel_joint" type="fixed">
      <parent>body</parent>
      <child>rl_wheel</child>
      <pose>0.5 0.25 0.0 0 0 0</pose> <!-- Position relative to body -->
    </joint>

    <!-- Rear right wheel -->
    <link name="rr_wheel">
      <visual name="rr_wheel_visual">
        <geometry>
          <cylinder>
            <radius>0.1</radius>
            <length>0.1</length>
          </cylinder>
        </geometry>
        <material>
          <ambient>0.8 0.2 0.2 1</ambient> <!-- Color Red -->
        </material>
      </visual>
      <collision name="rr_wheel_collision">
        <geometry>
          <cylinder>
            <radius>0.1</radius>
            <length>0.1</length>
          </cylinder>
        </geometry>
      </collision>
      <inertial>
        <mass>0.5</mass>
        <inertia>
          <ixx>0.002</ixx>
          <iyy>0.002</iyy>
          <izz>0.004</izz>
        </inertia>
      </inertial>
    </link>

    <joint name="rr_wheel_joint" type="fixed">
      <parent>body</parent>
      <child>rr_wheel</child>
      <pose>0.5 -0.25 0.0 0 0 0</pose> <!-- Position relative to body -->
    </joint>

  </model>
</sdf>
